Workbook

Sheet Capa
D9: Análise Financeira - Lava Rápido Nogueira - IJR
D19: Coordenador
D20: Nicholas De Tommaso
D24: Consultores
D25: Enzo Flosi
D26: João Nery
D27: Joana Gregorin
D28: Laura Calles
D29: Leonardo Tang

Sheet Macro - Itaú
D4: Lava Rápido Nogueira - IJR
I5: 2026 | J5: 2027E | K5: 2028E | L5: 2029E | M5: 2030E | N5: 2031E | O5: 2032E | P5: 2033E | Q5: 2034E | R5: 2035E | S5: 2036E
D7: Inflação
D8: IPCA | I8: 0.053535658 | J8: 0.045466259 | K8: 0.04 | L8: 0.039494898 | M8: =L8 -> 0.039494898 | N8: =M8 -> 0.039494898 | O8: =N8 -> 0.039494898 | P8: =O8 -> 0.039494898 | Q8: =P8 -> 0.039494898 | R8: =Q8 -> 0.039494898 | S8: =R8 -> 0.039494898
D9: IGP-M | I9: 0.054967004 | J9: 0.043005223 | K9: 0.04 | L9: 0.035 | M9: =L9 -> 0.035 | N9: =M9 -> 0.035 | O9: =N9 -> 0.035 | P9: =O9 -> 0.035 | Q9: =P9 -> 0.035 | R9: =Q9 -> 0.035 | S9: =R9 -> 0.035
D12: Taxa de Juros
D13: Selic – final do ano | I13: 0.14 | J13: 0.125 | K13: 0.115 | L13: 0.1075 | M13: =L13 -> 0.1075 | N13: =M13 -> 0.1075 | O13: =N13 -> 0.1075 | P13: =O13 -> 0.1075 | Q13: =P13 -> 0.1075 | R13: =Q13 -> 0.1075 | S13: =R13 -> 0.1075
D14: Selic – média do ano | I14: 0.14354167 | J14: 0.13125 | K14: 0.11708333 | L14: 0.11625 | M14: =L14 -> 0.11625 | N14: =M14 -> 0.11625 | O14: =N14 -> 0.11625 | P14: =O14 -> 0.11625 | Q14: =P14 -> 0.11625 | R14: =Q14 -> 0.11625 | S14: =R14 -> 0.11625
D15: CDI - final do ano (anualizado) | I15: 0.1388111 | J15: 0.12383212 | K15: 0.11384522 | L15: 0.1063575 | M15: =L15 -> 0.1063575 | N15: =M15 -> 0.1063575 | O15: =N15 -> 0.1063575 | P15: =O15 -> 0.1063575 | Q15: =P15 -> 0.1063575 | R15: =Q15 -> 0.1063575 | S15: =R15 -> 0.1063575
D16: CDI - acumulado no ano | I16: 0.14280475 | J16: 0.13071503 | K16: 0.11653196 | L16: 0.10788111 | M16: =L16 -> 0.10788111 | N16: =M16 -> 0.10788111 | O16: =N16 -> 0.10788111 | P16: =O16 -> 0.10788111 | Q16: =P16 -> 0.10788111 | R16: =Q16 -> 0.10788111 | S16: =R16 -> 0.10788111

Sheet Input
E4: Lava Rápido Nogueira - IJR
J5: 42004 | K5: 2015 | L5: 2016 | M5: 2017 | N5: 2018 | O5: 2019 | P5: 2020 | Q5: 2021 | R5: 2022 | S5: 2023 | T5: 2024 | U5: 2025 | V5: 1S 2026
C7: DRE
C9: (=) Receita Bruta | K9: 490112 | L9: 504322 | M9: 495550 | N9: 468438 | O9: 442704 | P9: 356349 | Q9: 403942 | R9: 398406 | S9: 372588 | T9: 345060 | U9: 328251 | V9: 162400
C10: % YoY | L10: =L9/K9-1 -> 0.028993373 | M10: =M9/L9-1 -> -0.017393649 | N10: =N9/M9-1 -> -0.054710927 | O10: =O9/N9-1 -> -0.054935765 | P10: =P9/O9-1 -> -0.19506262 | Q10: =Q9/P9-1 -> 0.13355727 | R10: =R9/Q9-1 -> -0.013704938 | S10: =S9/R9-1 -> -0.064803241 | ... V10: =V9/U9-1 -> -0.50525665
C12: (-) Deduções | K12: -48525 | L12: -45904 | M12: -41826 | N12: -36772 | O12: -33317 | P12: -24251 | Q12: -27059 | R12: -25902 | S12: -23010 | T12: -20854 | U12: -19894 | V12: -9962
C14: (=) Receita Líquida | K14: 441587 | L14: 458418 | M14: 453724 | N14: 431666 | O14: 409388 | P14: 332098 | Q14: 376882 | R14: 372505 | S14: 349578 | T14: 324207 | U14: 308358 | V14: 152439
C15: % YoY | L15: =L14/K14-1 -> 0.0381148 | M15: =M14/L14-1 -> -0.010239563 | N15: =N14/M14-1 -> -0.048615458 | O15: =O14/N14-1 -> -0.051609346 | P15: =P14/O14-1 -> -0.188794 | Q15: =Q14/P14-1 -> 0.13485176 | R15: =R14/Q14-1 -> -0.011613715 | S15: =S14/R14-1 -> -0.061548167 | ... V15: =V14/U14-1 -> -0.50564279
C17: (-) Custo dos Serviços Prestados | K17: -287633 | L17: -309689 | M17: -301724 | N17: -298402 | O17: -280030 | P17: -255526 | Q17: -263826 | R17: -277723 | S17: -251763 | T17: -252467 | U17: -255162 | V17: -130287
D18: Salários, Ordenados, 13o Salário e Férias | K18: -111370 | L18: -124373 | M18: -116812 | N18: -118932 | O18: -107784 | P18: -112859 | Q18: -100467 | R18: -110696 | S18: -98560 | T18: -105430 | U18: -113344 | V18: -60854
D19: FGTS | K19: -8910 | L19: -9950 | M19: -9345 | N19: -9515 | O19: -8622 | P19: -9029 | Q19: -8037 | R19: -8856 | S19: -7885 | T19: -8434 | U19: -9068 | V19: -4868
D20: Vale Transporte | K20: -9603 | L20: -10629 | M20: -9885 | N20: -10178 | O20: -9051 | P20: -9440 | Q20: -8223 | R20: -9050 | S20: -7658 | T20: -8012 | U20: -8400 | V20: -4388
D21: Serviços de Terceiros: Lavadores PJ | K21: -82307 | L21: -86544 | M21: -87155 | N21: -84743 | O21: -82750 | P21: -64732 | Q21: -78936 | R21: -80676 | S21: -72212 | T21: -68679 | U21: -64800 | V21: -30095
D22: Mão de Obra Avulsa e Diaristas | K22: -12483 | L22: -12830 | M22: -13638 | N22: -12961 | O22: -12326 | P22: -9350 | Q22: -12217 | R22: -12102 | S22: -11378 | T22: -10417 | U22: -9360 | V22: -4890
D23: Materiais de Consumo (shampoo, cera, pretinho, aromatizante) | K23: -31460 | L23: -32372 | M23: -31809 | N23: -30069 | O23: -28417 | P23: -22874 | Q23: -25929 | R23: -25574 | S23: -23916 | T23: -22149 | U23: -21070 | V23: -10424
D24: Água e Esgoto | K24: -15616 | L24: -16201 | M24: -16072 | N24: -15363 | O24: -14711 | P24: -12355 | Q24: -13807 | R24: -13885 | S24: -13302 | T24: -12649 | U24: -12310 | V24: -6174
D25: Energia Elétrica | K25: -9721 | L25: -10270 | M25: -10396 | N25: -10168 | O25: -9993 | P25: -9070 | Q25: -9884 | R25: -10287 | S25: -10254 | T25: -10153 | U25: -10214 | V25: -5219
D26: Uniformes e EPI | K26: -800 | L26: -885 | M26: -941 | N26: -969 | O26: -1006 | P26: -1049 | Q26: -1096 | R26: -1207 | S26: -1276 | T26: -1336 | U26: -1400 | V26: -731
D27: Manutenção de Máquinas e Equipamentos | K27: -5364 | L27: -5635 | M27: -5669 | N27: -5507 | O27: -5370 | P27: -4767 | Q27: -5232 | R27: -5393 | S27: -5318 | T27: -5210 | U27: -5197 | V27: -2643
C29: (=) Lucro Bruto | K29: 153953 | L29: 148728 | M29: 152000 | N29: 133264 | O29: 129357 | P29: 76573 | Q29: 113056 | R29: 94781 | S29: 97815 | T29: 71740 | U29: 53195 | V29: 22152
C30: % YoY | L30: =L29/K29-1 -> -0.033938929 | M30: =M29/L29-1 -> 0.021999892 | N30: =N29/M29-1 -> -0.12326316 | O30: =O29/N29-1 -> -0.029317745 | P30: =P29/O29-1 -> -0.40804904 | Q30: =Q29/P29-1 -> 0.47644731 | R30: =R29/Q29-1 -> -0.16164556 | S30: =S29/R29-1 -> 0.032010635 | ... V30: =V29/U29-1 -> -0.58356988
C31: % Margem Bruta | K31: =K29/K14 -> 0.34863572 | L31: =L29/L14 -> 0.32443752 | M31: =M29/M14 -> 0.33500542 | N31: =N29/N14 -> 0.30872017 | O31: =O29/O14 -> 0.31597653 | P31: =P29/P14 -> 0.23057351 | Q31: =Q29/Q14 -> 0.29997718 | R31: =R29/R14 -> 0.25444222 | ... V31: =V29/V14 -> 0.14531714
C33: (-) Despesas Operacionais | K33: =SUM(K34:K43) -> -101717 | L33: =SUM(L34:L43) -> -101739 | M33: =SUM(M34:M43) -> -102267 | N33: =SUM(N34:N43) -> -89332 | O33: =SUM(O34:O43) -> -85535 | P33: =SUM(P34:P43) -> -77856 | Q33: =SUM(Q34:Q43) -> -87247 | R33: =SUM(R34:R43) -> -86884 | ... V33: =SUM(V34:V43) -> -40372
D34: Aluguéis | K34: -22800 | L34: -24000 | M34: -24600 | N34: -25200 | O34: -25800 | P34: -26400 | Q34: -27000 | R34: -28800 | S34: -30000 | T34: -30600 | U34: -31200 | V34: -16200
D35: IPTU, Taxas e Alvará de Funcionamento | K35: -1943 | L35: -2151 | M35: -2286 | N35: -2354 | O35: -2442 | P35: -2547 | Q35: -2663 | R35: -2931 | S35: -3100 | T35: -3243 | U35: -3400 | V35: -1776
D36: Assessoria Contábil | K36: -2401 | L36: -5314 | M36: -5648 | N36: -5816 | O36: -6034 | P36: -6294 | Q36: -6578 | R36: -7240 | S36: -7658 | T36: -8012 | U36: -8400 | V36: -4388
D37: Telefones e Internet | K37: -1509 | L37: -1670 | M37: -1775 | N37: -1828 | O37: -1896 | P37: -1978 | Q37: -2067 | R37: -2276 | S37: -2408 | T37: -2519 | U37: -2640 | V37: -1379
D38: Software e Licenças de Uso | K38: -892 | L38: -986 | M38: -1049 | N38: -1080 | O38: -1120 | P38: -1168 | Q38: -1222 | R38: -1345 | S38: -1422 | T38: -1488 | U38: -1560 | V38: -815
D39: Material de Expediente e Limpeza | K39: -1086 | L39: -1202 | M39: -1278 | N39: -1315 | O39: -1364 | P39: -1424 | Q39: -1488 | R39: -1637 | S39: -1732 | T39: -1813 | U39: -1900 | V39: -993
D40: Seguros | K40: -1200 | L40: -1329 | M40: -1412 | N40: -1454 | O40: -1508 | P40: -1573 | Q40: -1645 | R40: -1810 | S40: -1915 | T40: -2003 | U40: -2100 | V40: -1097
D41: Propaganda e Publicidade | K41: -514 | L41: -569 | M41: -605 | N41: -623 | O41: -647 | P41: -674 | Q41: -705 | R41: -776 | S41: -820 | T41: -858 | U41: -900 | V41: -470
D42: Pró-labore | K42: -68000 | L42: -63000 | M42: -62000 | N42: -48000 | O42: -43000 | P42: -34000 | Q42: -42000 | R42: -38000 | S42: -34000 | T42: -30000 | U42: -27000 | V42: -12000
D43: Outras Despesas Operacionais | K43: -1372 | L43: -1518 | M43: -1614 | N43: -1662 | O43: -1724 | P43: -1798 | Q43: -1879 | R43: -2069 | S43: -2188 | T43: -2289 | U43: -2400 | V43: -1254
C45: (=) EBITDA | K45: =K29+K33 -> 52236 | L45: =L29+L33 -> 46989 | M45: =M29+M33 -> 49733 | N45: =N29+N33 -> 43932 | O45: =O29+O33 -> 43822 | P45: =P29+P33 -> -1283 | Q45: =Q29+Q33 -> 25809 | R45: =R29+R33 -> 7897 | ... V45: =V29+V33 -> -18220
C46: % YoY | L46: =L45/K45-1 -> -0.10044797 | M46: =M45/L45-1 -> 0.058396646 | N46: =N45/M45-1 -> -0.11664287 | O46: =O45/N45-1 -> -0.0025038696 | P46: =P45/O45-1 -> -1.0292775 | Q46: =Q45/P45-1 -> -21.116134 | R46: =R45/Q45-1 -> -0.69402147 | S46: =S45/R45-1 -> 0.59199696 | ... V46: =V45/U45-1 -> -0.35629747
C47: % Margem EBITDA | K47: =K45/K14 -> 0.11829153 | L47: =L45/L14 -> 0.10250252 | M47: =M45/M14 -> 0.10961069 | N47: =N45/N14 -> 0.10177313 | O47: =O45/O14 -> 0.10704271 | P47: =P45/P14 -> -0.0038633175 | Q47: =Q45/Q14 -> 0.06848032 | R47: =R45/R14 -> 0.021199715 | ... V47: =V45/V14 -> -0.11952322
C49: (-) Depreciação | K49: -11348 | L49: -12730 | M49: -14578 | N49: -13976 | O49: -15085 | P49: -17412 | Q49: -16773 | R49: -16990 | S49: -15408 | T49: -16073 | U49: -15261 | V49: -7332
C51: (=) EBIT | K51: =K45+K49 -> 40888 | L51: =L45+L49 -> 34259 | M51: =M45+M49 -> 35155 | N51: =N45+N49 -> 29956 | O51: =O45+O49 -> 28737 | P51: =P45+P49 -> -18695 | Q51: =Q45+Q49 -> 9036 | R51: =R45+R49 -> -9093 | ... V51: =V45+V49 -> -25552
C52: % YoY | L52: =L51/K51-1 -> -0.16212581 | M52: =M51/L51-1 -> 0.026153711 | N52: =N51/M51-1 -> -0.14788792 | O52: =O51/N51-1 -> -0.040693016 | P52: =P51/O51-1 -> -1.650555 | Q52: =Q51/P51-1 -> -1.4833378 | R52: =R51/Q51-1 -> -2.0063081 | S52: =S51/R51-1 -> -0.68811173 | ... V52: =V51/U51-1 -> -0.41348758
C53: % Margem EBIT | K53: =K51/K14 -> 0.092593306 | L53: =L51/L14 -> 0.074733104 | M53: =M51/M14 -> 0.077481024 | N53: =N51/N14 -> 0.069396246 | O53: =O51/O14 -> 0.070195023 | P53: =P51/P14 -> -0.056293624 | Q53: =Q51/Q14 -> 0.023975674 | R53: =R51/R14 -> -0.024410411 | ... V53: =V51/V14 -> -0.16762115
...

Sheet Modelo
E4: Lava Rápido Nogueira - IJR
K5: 1S 2026 | L5: 2S 2026E | M5: 2026E | N5: 2027E | O5: 2028E | P5: 2029E | Q5: 2030E | R5: 2031E | S5: 2032E | T5: 2033E | U5: 2034E | V5: 2035E | W5: 2036E
C7: Premissas
D9: Build - Up da Receita
D11: Ticket Médio B2C | K11: =K14*$J$14+K15*$J$15+K16*$J$16+K17*$J$17 -> 0 | L11: =L14*$J$14+L15*$J$15+L16*$J$16+L17*$J$17 -> 225 | M11: =M14*$J$14+M15*$J$15+M16*$J$16+M17*$J$17 -> 225 | N11: =N14*$J$14+N15*$J$15+N16*$J$16+N17*$J$17 -> 239.16741 | O11: =O14*$J$14+O15*$J$15+O16*$J$16+O17*$J$17 -> 252.91953 | P11: =P14*$J$14+P15*$J$15+P16*$J$16+P17*$J$17 -> 267.33466 | Q11: =Q14*$J$14+Q15*$J$15+Q16*$J$16+Q17*$J$17 -> 282.57137 | R11: =R14*$J$14+R15*$J$15+R16*$J$16+R17*$J$17 -> 298.6765 | ... W11: =W14*$J$14+W15*$J$15+W16*$J$16+W17*$J$17 -> 394.06286 | Z11: 2026 | AA11: 2027 | AB11: 2028 | AC11: 2029 | AD11: 2030 | AE11: 2031 | AF11: 2032 | AG11: 2033 | AH11: 2034 | AI11: 2035 | AJ11: 2036
D13: Repasse - Inflação de Serviços - Inflação | J13: 0.0175
D14: Preço Lavagem Completa | J14: 0.45 | K14: 0 | L14: 80 | M14: =L14 -> 80 | N14: =M14*(1+'Macro - Itaú'!J8+$J$13) -> 85.037301 | O14: =N14*(1+'Macro - Itaú'!K8+$J$13) -> 89.926946 | P14: =O14*(1+'Macro - Itaú'!L8+$J$13) -> 95.052323 | Q14: =P14*(1+'Macro - Itaú'!M8+$J$13) -> 100.46982 | R14: =Q14*(1+'Macro - Itaú'!N8+$J$13) -> 106.19609 | S14: =R14*(1+'Macro - Itaú'!O8+$J$13) -> 112.24872 | T14: =S14*(1+'Macro - Itaú'!P8+$J$13) -> 118.64633 | U14: =T14*(1+'Macro - Itaú'!Q8+$J$13) -> 125.40856 | ... W14: =V14*(1+'Macro - Itaú'!S8+$J$13) -> 140.11124
D15: Preço Lavagem Externa | J15: 0.25 | K15: 0 | L15: 70 | M15: =L15 -> 70 | N15: =M15*(1+'Macro - Itaú'!J8+$J$13) -> 74.407638 | O15: =N15*(1+'Macro - Itaú'!K8+$J$13) -> 78.686077 | P15: =O15*(1+'Macro - Itaú'!L8+$J$13) -> 83.170782 | Q15: =P15*(1+'Macro - Itaú'!M8+$J$13) -> 87.911093 | R15: =Q15*(1+'Macro - Itaú'!N8+$J$13) -> 92.921576 | S15: =R15*(1+'Macro - Itaú'!O8+$J$13) -> 98.217632 | T15: =S15*(1+'Macro - Itaú'!P8+$J$13) -> 103.81554 | U15: =T15*(1+'Macro - Itaú'!Q8+$J$13) -> 109.73249 | ... W15: =V15*(1+'Macro - Itaú'!S8+$J$13) -> 122.59733
D16: Preço Lavagem Completa + Cera | J16: 0.2 | K16: 0 | L16: 320 | M16: =L16 -> 320 | N16: =M16*(1+'Macro - Itaú'!J8+$J$13) -> 340.1492 | O16: =N16*(1+'Macro - Itaú'!K8+$J$13) -> 359.70778 | P16: =O16*(1+'Macro - Itaú'!L8+$J$13) -> 380.20929 | Q16: =P16*(1+'Macro - Itaú'!M8+$J$13) -> 401.87928 | R16: =Q16*(1+'Macro - Itaú'!N8+$J$13) -> 424.78435 | S16: =R16*(1+'Macro - Itaú'!O8+$J$13) -> 448.99489 | T16: =S16*(1+'Macro - Itaú'!P8+$J$13) -> 474.58531 | U16: =T16*(1+'Macro - Itaú'!Q8+$J$13) -> 501.63425 | ... W16: =V16*(1+'Macro - Itaú'!S8+$J$13) -> 560.44495
D17: Preço Lavagem Completa + Externa + Polimento | J17: 0.1 | K17: 0 | L17: 1075 | M17: =L17 -> 1075 | N17: =M17*(1+'Macro - Itaú'!J8+$J$13) -> 1142.6887 | O17: =N17*(1+'Macro - Itaú'!K8+$J$13) -> 1208.3933 | P17: =O17*(1+'Macro - Itaú'!L8+$J$13) -> 1277.2656 | Q17: =P17*(1+'Macro - Itaú'!M8+$J$13) -> 1350.0632 | R17: =Q17*(1+'Macro - Itaú'!N8+$J$13) -> 1427.0099 | S17: =R17*(1+'Macro - Itaú'!O8+$J$13) -> 1508.3422 | T17: =S17*(1+'Macro - Itaú'!P8+$J$13) -> 1594.31 | U17: =T17*(1+'Macro - Itaú'!Q8+$J$13) -> 1685.1776 | ... W17: =V17*(1+'Macro - Itaú'!S8+$J$13) -> 1882.7448
D18: Fator de Período (ano = 1,0) | K18: 0.5 | L18: 0.5 | M18: 1 | N18: 1 | O18: 1 | P18: 1 | Q18: 1 | R18: 1 | S18: 1 | T18: 1 | U18: 1 | V18: 1 | W18: 1
D20: Quantidade Total de Lavagens Orgânico B2C | K20: =K50 -> 674 | L20: =L50 -> 863 | M20: =M50 -> 1537 | N20: =N50 -> 2426 | O20: =O50 -> 3010 | P20: =P50 -> 3503 | Q20: =Q50 -> 3906 | R20: =R50 -> 4246 | ... W20: =W50 -> 5235
L22: Mix Maduro | M22: Mix Inicial | N22: Freq. Histórica
D23: Taxa de Retenção (2023 - 2025) | J23: 0.7856 | K23: Retidos | L23: 0.93 | M23: =$J$23/SUM($J$23:$J$25) -> 0.86367634 | N23: 5.04
D24: Taxa de Reativação (2023 - 2025) | J24: 0.0712 | K24: Reativados | L24: 0.045 | M24: =$J$24/SUM($J$23:$J$25) -> 0.078276165 | N24: 1.79
D25: Taxa de Novos Clientes (2023 - 2025) | J25: 0.0528 | K25: Novos | L25: 0.025 | M25: =$J$25/SUM($J$23:$J$25) -> 0.058047493 | N25: 3.48
D27: Frequência Média Inicial (2023 - 2025) | J27: 4.7
D28: Frequência Média Alvo (Madura) | J28: 24
D29: Teto de Maturidade (assíntota) | J29: 0.8
D30: Velocidade de Convergência (% do gap fechado por ano) | J30: 0.2
D31: Frequência Madura Efetiva (implícita) | J31: =$J$27+($J$28-$J$27)*$J$29 -> 20.14
D32: Taxa de Crescimento de Clientes Anual | J32: 0.03
D34: Maturidade Operacional | K34: =(K49-$J$27)/($J$28-$J$27) -> 0.046632124 | L34: =K34+($J$29-K34)*$J$30*L18 -> 0.12196891 | M34: =L34 -> 0.12196891 | N34: =M34+($J$29-M34)*$J$30*N18 -> 0.25757513 | O34: =N34+($J$29-N34)*$J$30*O18 -> 0.3660601 | P34: =O34+($J$29-O34)*$J$30*P18 -> 0.45284808 | Q34: =P34+($J$29-P34)*$J$30*Q18 -> 0.52227847 | R34: =Q34+($J$29-Q34)*$J$30*R18 -> 0.57782277 | S34: =R34+($J$29-R34)*$J$30*S18 -> 0.62225822 | T34: =S34+($J$29-S34)*$J$30*T18 -> 0.65780657 | U34: =T34+($J$29-T34)*$J$30*U18 -> 0.68624526 | ... W34: =V34+($J$29-V34)*$J$30*W18 -> 0.72719697
D35: Fator de Crescimento Remanescente | K35: =1-K34 -> 0.95336788 | L35: =1-L34 -> 0.87803109 | M35: =1-M34 -> 0.87803109 | N35: =1-N34 -> 0.74242487 | O35: =1-O34 -> 0.6339399 | P35: =1-P34 -> 0.54715192 | Q35: =1-Q34 -> 0.47772153 | R35: =1-R34 -> 0.42217723 | ... W35: =1-W34 -> 0.27280303
D37: Taxa de Crescimento Efetiva de Clientes Anual | K37: 0 | L37: =$J$32*L35 -> 0.026340933 | M37: =$J$32*M35 -> 0.026340933 | N37: =$J$32*N35 -> 0.022272746 | O37: =$J$32*O35 -> 0.019018197 | P37: =$J$32*P35 -> 0.016414558 | Q37: =$J$32*Q35 -> 0.014331646 | R37: =$J$32*R35 -> 0.012665317 | S37: =$J$32*S35 -> 0.011332253 | ... W37: =$J$32*W35 -> 0.008184091
D39: Mix - Retidos (% da base) | K39: =($M$23+($L$23-$M$23)*K$34)/(($M$23+($L$23-$M$23)*K$34)+($M$24+($L$24-$M$24)*K$34)+($M$25+($L$25-$M$25)*K$34)) -> 0.86676915 | L39: =($M$23+($L$23-$M$23)*L$34)/(($M$23+($L$23-$M$23)*L$34)+($M$24+($L$24-$M$24)*L$34)+($M$25+($L$25-$M$25)*L$34)) -> 0.87176577 | M39: =($M$23+($L$23-$M$23)*M$34)/(($M$23+($L$23-$M$23)*M$34)+($M$24+($L$24-$M$24)*M$34)+($M$25+($L$25-$M$25)*M$34)) -> 0.87176577 | N39: =($M$23+($L$23-$M$23)*N$34)/(($M$23+($L$23-$M$23)*N$34)+($M$24+($L$24-$M$24)*N$34)+($M$25+($L$25-$M$25)*N$34)) -> 0.88075967 | O39: =($M$23+($L$23-$M$23)*O$34)/(($M$23+($L$23-$M$23)*O$34)+($M$24+($L$24-$M$24)*O$34)+($M$25+($L$25-$M$25)*O$34)) -> 0.88795479 | P39: =($M$23+($L$23-$M$23)*P$34)/(($M$23+($L$23-$M$23)*P$34)+($M$24+($L$24-$M$24)*P$34)+($M$25+($L$25-$M$25)*P$34)) -> 0.89371088 | Q39: =($M$23+($L$23-$M$23)*Q$34)/(($M$23+($L$23-$M$23)*Q$34)+($M$24+($L$24-$M$24)*Q$34)+($M$25+($L$25-$M$25)*Q$34)) -> 0.89831576 | R39: =($M$23+($L$23-$M$23)*R$34)/(($M$23+($L$23-$M$23)*R$34)+($M$24+($L$24-$M$24)*R$34)+($M$25+($L$25-$M$25)*R$34)) -> 0.90199966 | ... W39: =($M$23+($L$23-$M$23)*W$34)/(($M$23+($L$23-$M$23)*W$34)+($M$24+($L$24-$M$24)*W$34)+($M$25+($L$25-$M$25)*W$34)) -> 0.9119067
D40: Mix - Reativados (% da base) | K40: =($M$24+($L$24-$M$24)*K$34)/(($M$23+($L$23-$M$23)*K$34)+($M$24+($L$24-$M$24)*K$34)+($M$25+($L$25-$M$25)*K$34)) -> 0.076724427 | L40: =($M$24+($L$24-$M$24)*L$34)/(($M$23+($L$23-$M$23)*L$34)+($M$24+($L$24-$M$24)*L$34)+($M$25+($L$25-$M$25)*L$34)) -> 0.074217508 | M40: =($M$24+($L$24-$M$24)*M$34)/(($M$23+($L$23-$M$23)*M$34)+($M$24+($L$24-$M$24)*M$34)+($M$25+($L$25-$M$25)*M$34)) -> 0.074217508 | N40: =($M$24+($L$24-$M$24)*N$34)/(($M$23+($L$23-$M$23)*N$34)+($M$24+($L$24-$M$24)*N$34)+($M$25+($L$25-$M$25)*N$34)) -> 0.069705053 | O40: =($M$24+($L$24-$M$24)*O$34)/(($M$23+($L$23-$M$23)*O$34)+($M$24+($L$24-$M$24)*O$34)+($M$25+($L$25-$M$25)*O$34)) -> 0.066095089 | P40: =($M$24+($L$24-$M$24)*P$34)/(($M$23+($L$23-$M$23)*P$34)+($M$24+($L$24-$M$24)*P$34)+($M$25+($L$25-$M$25)*P$34)) -> 0.063207118 | Q40: =($M$24+($L$24-$M$24)*Q$34)/(($M$23+($L$23-$M$23)*Q$34)+($M$24+($L$24-$M$24)*Q$34)+($M$25+($L$25-$M$25)*Q$34)) -> 0.060896741 | R40: =($M$24+($L$24-$M$24)*R$34)/(($M$23+($L$23-$M$23)*R$34)+($M$24+($L$24-$M$24)*R$34)+($M$25+($L$25-$M$25)*R$34)) -> 0.059048439 | ... W40: =($M$24+($L$24-$M$24)*W$34)/(($M$23+($L$23-$M$23)*W$34)+($M$24+($L$24-$M$24)*W$34)+($M$25+($L$25-$M$25)*W$34)) -> 0.054077839
D41: Mix - Novos (% da base) | K41: =1-K39-K40 -> 0.056506419 | L41: =1-L39-L40 -> 0.054016727 | M41: =1-M39-M40 -> 0.054016727 | N41: =1-N39-N40 -> 0.049535281 | O41: =1-O39-O40 -> 0.045950125 | P41: =1-P39-P40 -> 0.043081999 | Q41: =1-Q39-Q40 -> 0.040787499 | R41: =1-R39-R40 -> 0.038951899 | ... W41: =1-W39-W40 -> 0.034015456
D43: Clientes Retidos | K43: =ROUND(K$47*K39,0) -> 209 | L43: =ROUND(L$47*L39,0) -> 213 | M43: =ROUND(M$47*M39,0) -> 213 | N43: =ROUND(N$47*N39,0) -> 219 | O43: =ROUND(O$47*O39,0) -> 225 | P43: =ROUND(P$47*P39,0) -> 230 | Q43: =ROUND(Q$47*Q39,0) -> 234 | R43: =ROUND(R$47*R39,0) -> 237 | ... W43: =ROUND(W$47*W39,0) -> 249
D44: Clientes Reativados | K44: =ROUND(K$47*K40,0) -> 18 | L44: =ROUND(L$47*L40,0) -> 18 | M44: =ROUND(M$47*M40,0) -> 18 | N44: =ROUND(N$47*N40,0) -> 17 | O44: =ROUND(O$47*O40,0) -> 17 | P44: =ROUND(P$47*P40,0) -> 16 | Q44: =ROUND(Q$47*Q40,0) -> 16 | R44: =ROUND(R$47*R40,0) -> 16 | ... W44: =ROUND(W$47*W40,0) -> 15
D45: Clientes Novos | K45: =K$47-K43-K44 -> 14 | L45: =L$47-L43-L44 -> 13 | M45: =M$47-M43-M44 -> 13 | N45: =N$47-N43-N44 -> 13 | O45: =O$47-O43-O44 -> 11 | P45: =P$47-P43-P44 -> 11 | Q45: =Q$47-Q43-Q44 -> 10 | R45: =R$47-R43-R44 -> 10 | ... W45: =W$47-W43-W44 -> 9
D47: Base de Clientes Ativos | K47: 241 | L47: =ROUNDDOWN(K47*(1+L37*L18),0) -> 244 | M47: =L47 -> 244 | N47: =ROUNDDOWN(M47*(1+N37*N18),0) -> 249 | O47: =ROUNDDOWN(N47*(1+O37*O18),0) -> 253 | P47: =ROUNDDOWN(O47*(1+P37*P18),0) -> 257 | Q47: =ROUNDDOWN(P47*(1+Q37*Q18),0) -> 260 | R47: =ROUNDDOWN(Q47*(1+R37*R18),0) -> 263 | S47: =ROUNDDOWN(R47*(1+S37*S18),0) -> 265 | T47: =ROUNDDOWN(S47*(1+T37*T18),0) -> 267 | U47: =ROUNDDOWN(T47*(1+U37*U18),0) -> 269 | ... W47: =ROUNDDOWN(V47*(1+W37*W18),0) -> 273
D49: Frequência Média de Lavagens (ajustada pelo mix) | K49: 5.6 | L49: =($J$27+($J$28-$J$27)*L$34)*(L39*$N$23+L40*$N$24+L41*$N$25)/$J$27 -> 7.0758029 | M49: =($J$27+($J$28-$J$27)*M$34)*(M39*$N$23+M40*$N$24+M41*$N$25)/$J$27 -> 7.0758029 | N49: =($J$27+($J$28-$J$27)*N$34)*(N39*$N$23+N40*$N$24+N41*$N$25)/$J$27 -> 9.7456549 | O49: =($J$27+($J$28-$J$27)*O$34)*(O39*$N$23+O40*$N$24+O41*$N$25)/$J$27 -> 11.898902 | P49: =($J$27+($J$28-$J$27)*P$34)*(P39*$N$23+P40*$N$24+P41*$N$25)/$J$27 -> 13.632614 | Q49: =($J$27+($J$28-$J$27)*Q$34)*(Q39*$N$23+Q40*$N$24+Q41*$N$25)/$J$27 -> 15.026696 | R49: =($J$27+($J$28-$J$27)*R$34)*(R39*$N$23+R40*$N$24+R41*$N$25)/$J$27 -> 16.146515 | S49: =($J$27+($J$28-$J$27)*S$34)*(S39*$N$23+S40*$N$24+S41*$N$25)/$J$27 -> 17.045283 | ... W49: =($J$27+($J$28-$J$27)*W$34)*(W39*$N$23+W40*$N$24+W41*$N$25)/$J$27 -> 19.178093
D50: Quantidade Orgânica de Lavagens | K50: =ROUNDDOWN(K47*K49*K18,0) -> 674 | L50: =ROUNDDOWN(L47*L49*L18,0) -> 863 | M50: =K50+L50 -> 1537 | N50: =ROUNDDOWN(N47*N49*N18,0) -> 2426 | O50: =ROUNDDOWN(O47*O49*O18,0) -> 3010 | P50: =ROUNDDOWN(P47*P49*P18,0) -> 3503 | Q50: =ROUNDDOWN(Q47*Q49*Q18,0) -> 3906 | R50: =ROUNDDOWN(R47*R49*R18,0) -> 4246 | S50: =ROUNDDOWN(S47*S49*S18,0) -> 4516 | T50: =ROUNDDOWN(T47*T49*T18,0) -> 4743 | U50: =ROUNDDOWN(U47*U49*U18,0) -> 4934 | ... W50: =ROUNDDOWN(W47*W49*W18,0) -> 5235
D54: Ticket Médio B2B | K54: =K56 -> 0 | L54: =L56 -> 89 | M54: =M56 -> 89 | N54: =N56 -> 93.046497 | O54: =O56 -> 96.768357 | P54: =P56 -> 100.59021 | Q54: =Q56 -> 104.56301 | R54: =R56 -> 108.69272 | ... W54: =W56 -> 131.92049
D56: Preço Lavagem Completa | K56: 0 | L56: 89 | M56: =L56 -> 89 | N56: =M56*(1+'Macro - Itaú'!J8) -> 93.046497 | O56: =N56*(1+'Macro - Itaú'!K8) -> 96.768357 | P56: =O56*(1+'Macro - Itaú'!L8) -> 100.59021 | Q56: =P56*(1+'Macro - Itaú'!M8) -> 104.56301 | R56: =Q56*(1+'Macro - Itaú'!N8) -> 108.69272 | S56: =R56*(1+'Macro - Itaú'!O8) -> 112.98553 | T56: =S56*(1+'Macro - Itaú'!P8) -> 117.44788 | U56: =T56*(1+'Macro - Itaú'!Q8) -> 122.08647 | ... W56: =V56*(1+'Macro - Itaú'!S8) -> 131.92049
D58: B2B
D60: Viagens de Carro/Dia em São Paulo | J60: 12000000
D61: Carros Circulando/Dia em São Paulo | J61: 6500000
D62: Fator de Conversão (Veículos/Viagens) | J62: =J61/J60 -> 0.54166667
...

Sheet Valuation
D4: Lava Rápido Nogueira - IJR
J5: 2026E | K5: 2027E | L5: 2028E | M5: 2029E | N5: 2030E | O5: 2031E | P5: 2032E | Q5: 2033E | R5: 2034E | S5: 2035E | T5: 2036E | U5: Perpetuidade
C7: WACC
C9: Mister Car Wash
C10: Beta Alavancado | I10: 1.259
C11: D/E | I11: =43.3/56.7 -> 0.76366843
C12: Beta Desalavancado | I12: =I10/(1+(1-I51)*I11) -> 0.80296429
C14: Driven Brands
C15: Beta Alavancado | I15: 1.044
C16: D/E | I16: =51.5/48.5 -> 1.0618557
C17: Beta Desalavancado | I17: =I15/(1+(1-I51)*I16) -> 0.58333732
C19: Monro
C20: Beta Alavancado | I20: 0.976
C21: D/E | I21: =49.5/50.5 -> 0.98019802
C22: Beta Desalavancado | I22: =I20/(1+(1-I51)*I21) -> 0.56449687
C24: AutoZone
C25: Beta Alavancado | I25: 0.548
C26: D/E | I26: =18.1/81.9 -> 0.22100122
C27: Beta Desalavancado | I27: =I25/(1+(1-I51)*I26) -> 0.47064538
C29: O'Reilly Automotive
C30: Beta Alavancado | I30: 0.463
C31: D/E | I31: =11.3/88.7 -> 0.12739572
C32: Beta Desalavancado | I32: =I30/(1+(1-I51)*I31) -> 0.42292985
C34: Advance Auto Parts
C35: Beta Alavancado | I35: 0.897
C36: D/E | I36: =0.6/0.4 -> 1.5
C37: Beta Desalavancado | I37: =I35/(1+(1-I51)*I36) -> 0.42400321
C39: Valvoline
C40: Beta Alavancado | I40: 0.677
C41: D/E | I41: =32.1/67.9 -> 0.47275405
C42: Beta Desalavancado | I42: =I40/(1+(1-I51)*I41) -> 0.50089259
C45: Média Ponderada dos Betas Desalavancados | I45: =I12*0.5+AVERAGE(I17,I22,I27,I32,I37,I42)*0.5 -> 0.64867425
C48: Risk Free (BR) | I48: 0.149649 | J48: Projeção Curva de Juros Prefixado 10 anos Anbima
C49: Risk Free (EUA) | I49: 0.0517 | J49: Fred 30 Year Treasure Yield
C51: Imposto de Renda dos EUA | I51: 0.2563
C52: Imposto de Renda do Brasil | I52: =AVERAGE(Modelo!N237:W237) -> 0.19
C54: Beta Alavancado | I54: =I45*(1+(1-I52)*(I56/I57)) -> 0.68982023
C56: D | I56: =Modelo!W270+Modelo!W274 -> 133333.33
C57: E | I57: =Modelo!W276 -> 1702640.4
C58: D/D+E | I58: =I56/(I56+I57) -> 0.072622681
...

Sheet 2026 LR 
A1: mn
A2: Preencher apenas as células em azul (inputs). As demais são calculadas.
A4: 1. DADOS PRINCIPAIS
A5: Descrição | B5: Valor (R$) | C5: Observações
A6: Receita Bruta | B6: =Modelo!M200 -> 522738.64
A7: (-) Deduções da Receita Bruta | B7: =-$K$214 -> 0 | C7: Devoluções, descontos, tributos sobre vendas
A8: (=) Receita Líquida | B8: =B6-B7 -> 522738.64
A9: (-) Despesas Dedutíveis | C9: Necessárias e usuais à atividade (art. 311 RIR/18)
A10: (=) Resultado Contábil (LAIR) | B10: =B8-B9 -> 522738.64
A11: (+) Adições — Despesas Indedutíveis | C11: Multas, brindes, doações, provisões não dedutíveis
A12: (-) Exclusões | C12: Receitas não tributáveis, equivalência patrimonial
A13: (-) Compensação de Prejuízo Fiscal | C13: Limitada a 30% do lucro ajustado
A14: (=) BASE DE CÁLCULO — LUCRO REAL | B14: =B10+B11-B12-B13 -> #VALUE!
A15: Limite Anual (adicional de IRPJ) | B15: 240000 | C15: R$ 20.000/mês × 12 meses
A16: Excedente ao Limite Anual | B16: =MAX(B14-B15,0) -> #VALUE!
A19: 2. TRIBUTOS
A20: Tributo | B20: Base de Cálculo (R$) | C20: Alíquota | D20: Resultado (R$)
A21: IRPJ | B21: =B14 -> #VALUE! | C21: 0.15 | D21: =B21*C21 -> #VALUE!
A22: IRPJ — Adicional | B22: =B16 -> #VALUE! | C22: 0.1 | D22: =B22*C22 -> #VALUE!
A23: CSLL | B23: =B14 -> #VALUE! | C23: 0.09 | D23: =B23*C23 -> #VALUE!
A24: PIS (não cumulativo) | B24: =B6 -> 522738.64 | C24: 0.0165 | D24: =B24*C24 -> 8625.1876
A25: COFINS (não cumulativo) | B25: =B6 -> 522738.64 | C25: 0.076 | D25: =B25*C25 -> 39728.137
A26: ISS | B26: =B8 -> 522738.64 | C26: 0.05 | D26: =B26*C26 -> 26136.932
A27: IBS (Reforma Tributária) | B27: =B8 -> 522738.64 | C27: 0.001 | D27: =B27*C27 -> 522.73864
A28: CBS (Reforma Tributária) | B28: =B8 -> 522738.64 | C28: 0,9% | D28: =B28*C28 -> 4704.6478
A29: TOTAL DE TRIBUTOS | D29: =SUM(D21:D28) -> #VALUE!
A31: Carga tributária efetiva / Receita Bruta | D31: =IFERROR(D29/B6,"-") -> -
A32: Lucro Líquido após tributos | D32: =B10-D29 -> #VALUE!

Sheet 2026 LP
A1: LUCRO PRESUMIDO — APURAÇÃO TRIMESTRAL 2026
A2: Preencher apenas as células em azul (inputs). Verde = link interno. Preto = fórmula.
A4: 1. DADOS PRINCIPAIS — RECEITA POR TRIMESTRE
A5: Trimestre | B5: Receita Bruta (R$) | C5: (-) Deduções (R$) | D5: (=) Receita Líquida (R$) | E5: Limite Adicional IRPJ (R$)
A6: 1º TRIMESTRE | B6: =Modelo!K200/2 -> 81200 | C6: =-#REF!/2 -> #REF! | D6: =B6-C6 -> #REF! | E6: 60000 | F6: R$ 20.000/mês × 3 meses = R$ 60.000 por trimestre
A7: 2º TRIMESTRE | B7: =B6 -> 81200 | C7: =-#REF!/2 -> #REF! | D7: =B7-C7 -> #REF! | E7: 60000
A8: 3º TRIMESTRE | B8: =Modelo!L200/2 -> 180169.32 | D8: =B8-C8 -> 180169.32 | E8: 60000
A9: 4º TRIMESTRE | B9: =B8 -> 180169.32 | D9: =B9-C9 -> 180169.32 | E9: 60000
A10: TOTAL ANUAL | B10: =SUM(B6:B9) -> 522738.64 | C10: =SUM(C6:C9) -> #REF! | D10: =SUM(D6:D9) -> #REF! | E10: =SUM(E6:E9) -> 240000
A13: 2. ALÍQUOTAS E PERCENTUAIS DE PRESUNÇÃO
A14: Parâmetro | B14: Alíquota | C14: Observações
A15: Presunção IRPJ | B15: 0.32 | C15: 8% comércio/indústria | 16% transporte | 32% serviços
A16: Presunção CSLL | B16: 0.32 | C16: 12% regra geral | 32% serviços
A17: IRPJ | B17: 0.15
A18: IRPJ — Adicional | B18: 0.1 | C18: Sobre a base que exceder o limite trimestral
A19: CSLL | B19: 0.09
A20: PIS (cumulativo) | B20: 0.0065 | C20: Incide sobre a receita bruta
A21: COFINS (cumulativo) | B21: 0.03 | C21: Incide sobre a receita bruta
A22: ICMS / ISS | B22: 0.05
A23: IBS | B23: 0,1% | C23: Reforma tributária — fase de transição
A24: CBS | B24: 0,9% | C24: Reforma tributária — fase de transição
A27: 3. APURAÇÃO DOS TRIBUTOS — POR TRIMESTRE
A28: Trimestre | B28: RECEITA | C28: IRPJ BASE | D28: IRPJ | E28: IRPJ ADICIONAL | F28: IRPJ TOTAL | G28: CSLL BASE | H28: CSLL | I28: PIS | J28: COFINS | K28: ICMS / ISS | L28: IBS | M28: CBS | N28: TOTAL IMPOSTOS
A29: 1º TRIMESTRE | B29: =B6 -> 81200 | C29: =B29*$B$15 -> 25984 | D29: =C29*$B$17 -> 3897.6 | E29: =IF(C29>E6,(C29-E6)*$B$18,0) -> 0 | F29: =D29+E29 -> 3897.6 | G29: =B29*$B$16 -> 25984 | H29: =G29*$B$19 -> 2338.56 | I29: =B29*$B$20 -> 527.8 | J29: =B29*$B$21 -> 2436 | K29: =B29*$B$22 -> 4060 | L29: =B29*$B$23 -> 81.2 | M29: =B29*$B$24 -> 730.8 | N29: =F29+H29+I29+J29+K29+L29+M29 -> 14071.96
A30: 2º TRIMESTRE | B30: =B7 -> 81200 | C30: =B30*$B$15 -> 25984 | D30: =C30*$B$17 -> 3897.6 | E30: =IF(C30>E7,(C30-E7)*$B$18,0) -> 0 | F30: =D30+E30 -> 3897.6 | G30: =B30*$B$16 -> 25984 | H30: =G30*$B$19 -> 2338.56 | I30: =B30*$B$20 -> 527.8 | J30: =B30*$B$21 -> 2436 | K30: =B30*$B$22 -> 4060 | L30: =B30*B23 -> 81.2 | M30: =B30*$B$24 -> 730.8 | N30: =F30+H30+I30+J30+K30+L30+M30 -> 14071.96
A31: 3º TRIMESTRE | B31: =B8 -> 180169.32 | C31: =B31*$B$15 -> 57654.182 | D31: =C31*$B$17 -> 8648.1274 | E31: =IF(C31>E8,(C31-E8)*$B$18,0) -> 0 | F31: =D31+E31 -> 8648.1274 | G31: =B31*$B$16 -> 57654.182 | H31: =G31*$B$19 -> 5188.8764 | I31: =B31*$B$20 -> 1171.1006 | J31: =B31*$B$21 -> 5405.0796 | K31: =B31*$B$22 -> 9008.466 | L31: =B31*$B$23 -> 180.16932 | M31: =B31*$B$24 -> 1621.5239 | N31: =F31+H31+I31+J31+K31+L31+M31 -> 31223.343
A32: 4º TRIMESTRE | B32: =B9 -> 180169.32 | C32: =B32*$B$15 -> 57654.182 | D32: =C32*$B$17 -> 8648.1274 | E32: =IF(C32>E9,(C32-E9)*$B$18,0) -> 0 | F32: =D32+E32 -> 8648.1274 | G32: =B32*$B$16 -> 57654.182 | H32: =G32*$B$19 -> 5188.8764 | I32: =B32*$B$20 -> 1171.1006 | J32: =B32*$B$21 -> 5405.0796 | K32: =B32*$B$22 -> 9008.466 | L32: =B32*$B$23 -> 180.16932 | M32: =B32*$B$24 -> 1621.5239 | N32: =F32+H32+I32+J32+K32+L32+M32 -> 31223.343
A33: TOTAL ANUAL | B33: =SUM(B29:B32) -> 522738.64 | C33: =SUM(C29:C32) -> 167276.36 | D33: =SUM(D29:D32) -> 25091.455 | E33: =SUM(E29:E32) -> 0 | F33: =SUM(F29:F32) -> 25091.455 | G33: =SUM(G29:G32) -> 167276.36 | H33: =SUM(H29:H32) -> 15054.873 | I33: =SUM(I29:I32) -> 3397.8012 | ... N33: =SUM(N29:N32) -> 90590.606
A36: Carga tributária efetiva sobre a Receita Bruta | B36: =IFERROR(N33/B33,"-") -> 0.1733
A37: Resultado após tributos (Receita Líquida − Tributos) | B37: =D10-N33 -> #REF!

Sheet Projeções - LR
A1: PROJEÇÃO ANUAL — LUCRO REAL (2027–2028)
A2: Empresa de serviços. Apuração anual do Lucro Real. Azul = input | Preto = fórmula. PIS e COFINS extintos desde 2027 — substituídos pela CBS.
A4: 1. PREMISSAS E BASE DE CÁLCULO
A5: Item | B5: 2027 | C5: 2028 | D5: Observações
A6: Receita Bruta | B6: =Modelo!N200 -> 934592.62 | C6: =Modelo!O200 -> 1158269.3 | D6: Input — ou vincule à aba Modelo
A7: (-) Deduções da Receita Bruta | D7: Devoluções, descontos e cancelamentos
A8: (=) Receita Líquida | B8: =B6-B7 -> 934592.62 | C8: =C6-C7 -> 1158269.3
A9: (-) Despesas Dedutíveis | D9: Custos e despesas necessários à atividade (art. 311 RIR/18)
A10: (=) Resultado Contábil (LAIR) | B10: =B8-B9 -> 934592.62 | C10: =C8-C9 -> 1158269.3
A11: (+) Adições — despesas indedutíveis | D11: Multas, brindes, doações e provisões não dedutíveis
A12: (-) Exclusões | D12: Receitas não tributáveis e equivalência patrimonial
A13: (-) Compensação de Prejuízo Fiscal | D13: Limitada a 30% do lucro ajustado do período
A14: (=) BASE DE CÁLCULO — LUCRO REAL | B14: =B10+B11-B12-B13 -> 934592.62 | C14: =C10+C11-C12-C13 -> 1158269.3
A17: 2. ALÍQUOTAS E PARÂMETROS (SERVIÇOS)
A18: Parâmetro | B18: 2027 | C18: 2028 | D18: Observações
A19: IRPJ | B19: 0.15 | C19: 0.15 | D19: Sobre o lucro real — não alterado pela reforma
A20: IRPJ — Adicional | B20: 0.1 | C20: 0.1 | D20: Sobre a base que exceder o limite anual
A21: Limite anual do adicional (R$) | B21: 240000 | C21: 240000 | D21: R$ 20.000/mês × 12 meses
A22: CSLL | B22: 0.09 | C22: 0.09 | D22: Sobre o lucro real — não alterada pela reforma
A23: ISS | B23: 0.05 | C23: 0.05 | D23: Input — entre 2% e 5% conforme o município. Sem alteração até 2028
A24: IBS | B24: 0.001 | C24: 0.001 | D24: 0,05% estadual + 0,05% municipal em 2027 e 2028
A25: CBS | B25: 0.099 | C25: 0.099 | D25: ~10% a 11% — substitui PIS/COFINS, com direito a créditos sobre insumos
A26: PIS / COFINS | B26: Extintos | C26: Extintos | D26: Não incidem em 2027 e 2028 — substituídos pela CBS
A29: 3. APURAÇÃO ANUAL
A30: Item | B30: 2027 | C30: 2028 | D30: Total 2027–2028
A31: Base de cálculo — Lucro Real | B31: =B14 -> 934592.62 | C31: =Modelo!O200 -> 1158269.3 | D31: =B31+C31 -> 2092861.9
A32: IRPJ | B32: =B31*B19 -> 140188.89 | C32: =C31*C19 -> 173740.4 | D32: =B32+C32 -> 313929.29 | BY32: Q§12º`|QWEFe231123 | CA32: q | CB32: qqq
A33: IRPJ — Adicional | B33: =IF(B31>B21,(B31-B21)*B20,0) -> 69459.262 | C33: =IF(C31>C21,(C31-C21)*C20,0) -> 91826.932 | D33: =B33+C33 -> 161286.19
A34: IRPJ Total | B34: =B32+B33 -> 209648.16 | C34: =C32+C33 -> 265567.33 | D34: =B34+C34 -> 475215.49
A35: CSLL | B35: =B31*B22 -> 84113.336 | C35: =C31*C22 -> 104244.24 | D35: =B35+C35 -> 188357.57
A36: ISS | B36: =B8*B23 -> 46729.631 | C36: =C8*C23 -> 57913.466 | D36: =B36+C36 -> 104643.1
A37: IBS | B37: =B8*B24 -> 934.59262 | C37: =C8*C24 -> 1158.2693 | D37: =B37+C37 -> 2092.8619
A38: CBS | B38: =B8*B25 -> 92524.67 | C38: =C8*C25 -> 114668.66 | D38: =B38+C38 -> 207193.33
A39: TOTAL DE TRIBUTOS | B39: =B34+B35+B36+B37+B38 -> 433950.39 | C39: =C34+C35+C36+C37+C38 -> 543551.97 | D39: =B39+C39 -> 977502.35
A40: Carga tributária / Receita Bruta | B40: =IFERROR(B39/B6,"-") -> 0.46432036 | C40: =IFERROR(C39/C6,"-") -> 0.46927943 | D40: =IFERROR(D39/(B6+C6),"-") -> 0.4670649
A41: Resultado após tributos | B41: =B10-B39 -> 500642.24 | C41: =C10-C39 -> 614717.35 | D41: =B41+C41 -> 1115359.6

Sheet Projeções - LP
A1: 600
A2: Empresa de serviços. Apuração do IRPJ/CSLL é sempre trimestral no Lucro Presumido. Azul = input | Preto = fórmula. PIS e COFINS extintos desde 2027.
A4: 1. PREMISSAS DE RECEITA
A5: Item | B5: 1T 2027 | C5: 2T 2027 | D5: 3T 2027 | E5: 4T 2027 | F5: 1T 2028 | G5: 2T 2028 | H5: 3T 2028 | I5: 4T 2028 | J5: Total 2027 | K5: Total 2028
A6: Receita Bruta | B6: 233648.25 | C6: 233648.25 | D6: 233648.25 | E6: 233648.25 | F6: 289567.25 | G6: 289567.25 | H6: 289567.25 | I6: 289567.25 | J6: =Modelo!N200 -> 934592.62 | K6: =Modelo!O200 -> 1158269.3
A7: (-) Deduções da Receita Bruta | J7: =SUM(B7:E7) -> 0 | K7: =SUM(F7:I7) -> 0
A8: (=) Receita Líquida | B8: =B6-B7 -> 233648.25 | C8: =C6-C7 -> 233648.25 | D8: =D6-D7 -> 233648.25 | E8: =E6-E7 -> 233648.25 | F8: =F6-F7 -> 289567.25 | G8: =G6-G7 -> 289567.25 | H8: =H6-H7 -> 289567.25 | I8: =I6-I7 -> 289567.25 | J8: =SUM(B8:E8) -> 934593 | K8: =SUM(F8:I8) -> 1158269
A10: 2. ALÍQUOTAS E PARÂMETROS (SERVIÇOS)
A11: Parâmetro | B11: Valor | C11: Observações
A12: Presunção IRPJ | B12: 0.32 | C12: 32% — prestação de serviços em geral
A13: Presunção CSLL | B13: 0.32 | C13: 32% — prestação de serviços em geral
A14: IRPJ | B14: 0.15 | C14: Não alterado pela reforma
A15: IRPJ — Adicional | B15: 0.1 | C15: Sobre a base que exceder o limite do trimestre
A16: Limite trimestral do adicional (R$) | B16: 60000 | C16: R$ 20.000/mês × 3 meses
A17: CSLL | B17: 0.09 | C17: Não alterada pela reforma
A18: ISS | B18: 0.05 | C18: Input — entre 2% e 5% conforme o município. Sem alteração até 2028
A19: IBS | B19: 0.001 | C19: 0,05% estadual + 0,05% municipal em 2027 e 2028
A20: CBS | B20: 0.099 | C20: ~10% a 11% — substitui PIS e COFINS a partir de 2027
A21: PIS / COFINS | B21: Extintos | C21: Não incidem em 2027 e 2028 — substituídos pela CBS
A24: 3. APURAÇÃO TRIMESTRAL
A25: Item | B25: 1T 2027 | C25: 2T 2027 | D25: 3T 2027 | E25: 4T 2027 | F25: 1T 2028 | G25: 2T 2028 | H25: 3T 2028 | I25: 4T 2028 | J25: Total 2027 | K25: Total 2028
A26: Receita Bruta | B26: =B6 -> 233648.25 | C26: =C6 -> 233648.25 | D26: =D6 -> 233648.25 | E26: =E6 -> 233648.25 | F26: =F6 -> 289567.25 | G26: =G6 -> 289567.25 | H26: =H6 -> 289567.25 | I26: =I6 -> 289567.25 | J26: =SUM(B26:E26) -> 934593 | K26: =SUM(F26:I26) -> 1158269
A27: Base de cálculo IRPJ (presumida) | B27: =B26*$B$12 -> 74767.44 | C27: =C26*$B$12 -> 74767.44 | D27: =D26*$B$12 -> 74767.44 | E27: =E26*$B$12 -> 74767.44 | F27: =F26*$B$12 -> 92661.52 | G27: =G26*$B$12 -> 92661.52 | H27: =H26*$B$12 -> 92661.52 | I27: =I26*$B$12 -> 92661.52 | J27: =SUM(B27:E27) -> 299069.76 | K27: =SUM(F27:I27) -> 370646.08
A28: IRPJ | B28: =B27*$B$14 -> 11215.116 | C28: =C27*$B$14 -> 11215.116 | D28: =D27*$B$14 -> 11215.116 | E28: =E27*$B$14 -> 11215.116 | F28: =F27*$B$14 -> 13899.228 | G28: =G27*$B$14 -> 13899.228 | H28: =H27*$B$14 -> 13899.228 | I28: =I27*$B$14 -> 13899.228 | J28: =SUM(B28:E28) -> 44860.464 | K28: =SUM(F28:I28) -> 55596.912
A29: IRPJ — Adicional | B29: =IF(B27>$B$16,(B27-$B$16)*$B$15,0) -> 1476.744 | C29: =IF(C27>$B$16,(C27-$B$16)*$B$15,0) -> 1476.744 | D29: =IF(D27>$B$16,(D27-$B$16)*$B$15,0) -> 1476.744 | E29: =IF(E27>$B$16,(E27-$B$16)*$B$15,0) -> 1476.744 | F29: =IF(F27>$B$16,(F27-$B$16)*$B$15,0) -> 3266.152 | G29: =IF(G27>$B$16,(G27-$B$16)*$B$15,0) -> 3266.152 | H29: =IF(H27>$B$16,(H27-$B$16)*$B$15,0) -> 3266.152 | I29: =IF(I27>$B$16,(I27-$B$16)*$B$15,0) -> 3266.152 | J29: =SUM(B29:E29) -> 5906.976 | K29: =SUM(F29:I29) -> 13064.608
A30: IRPJ Total | B30: =B28+B29 -> 12691.86 | C30: =C28+C29 -> 12691.86 | D30: =D28+D29 -> 12691.86 | E30: =E28+E29 -> 12691.86 | F30: =F28+F29 -> 17165.38 | G30: =G28+G29 -> 17165.38 | H30: =H28+H29 -> 17165.38 | I30: =I28+I29 -> 17165.38 | J30: =SUM(B30:E30) -> 50767.44 | K30: =SUM(F30:I30) -> 68661.52
A31: Base de cálculo CSLL (presumida) | B31: =B26*$B$13 -> 74767.44 | C31: =C26*$B$13 -> 74767.44 | D31: =D26*$B$13 -> 74767.44 | E31: =E26*$B$13 -> 74767.44 | F31: =F26*$B$13 -> 92661.52 | G31: =G26*$B$13 -> 92661.52 | H31: =H26*$B$13 -> 92661.52 | I31: =I26*$B$13 -> 92661.52 | J31: =SUM(B31:E31) -> 299069.76 | K31: =SUM(F31:I31) -> 370646.08
A32: CSLL | B32: =B31*$B$17 -> 6729.0696 | C32: =C31*$B$17 -> 6729.0696 | D32: =D31*$B$17 -> 6729.0696 | E32: =E31*$B$17 -> 6729.0696 | F32: =F31*$B$17 -> 8339.5368 | G32: =G31*$B$17 -> 8339.5368 | H32: =H31*$B$17 -> 8339.5368 | I32: =I31*$B$17 -> 8339.5368 | J32: =SUM(B32:E32) -> 26916.278 | K32: =SUM(F32:I32) -> 33358.147
A33: ISS | B33: =B26*$B$18 -> 11682.413 | C33: =C26*$B$18 -> 11682.413 | D33: =D26*$B$18 -> 11682.413 | E33: =E26*$B$18 -> 11682.413 | F33: =F26*$B$18 -> 14478.363 | G33: =G26*$B$18 -> 14478.363 | H33: =H26*$B$18 -> 14478.363 | I33: =I26*$B$18 -> 14478.363 | J33: =SUM(B33:E33) -> 46729.65 | K33: =SUM(F33:I33) -> 57913.45
A34: IBS | B34: =B26*$B$19 -> 233.64825 | C34: =C26*$B$19 -> 233.64825 | D34: =D26*$B$19 -> 233.64825 | E34: =E26*$B$19 -> 233.64825 | F34: =F26*$B$19 -> 289.56725 | G34: =G26*$B$19 -> 289.56725 | H34: =H26*$B$19 -> 289.56725 | I34: =I26*$B$19 -> 289.56725 | J34: =SUM(B34:E34) -> 934.593 | K34: =SUM(F34:I34) -> 1158.269
A35: CBS | B35: =B26*$B$20 -> 23131.177 | C35: =C26*$B$20 -> 23131.177 | D35: =D26*$B$20 -> 23131.177 | E35: =E26*$B$20 -> 23131.177 | F35: =F26*$B$20 -> 28667.158 | G35: =G26*$B$20 -> 28667.158 | H35: =H26*$B$20 -> 28667.158 | I35: =I26*$B$20 -> 28667.158 | J35: =SUM(B35:E35) -> 92524.707 | K35: =SUM(F35:I35) -> 114668.63
A36: TOTAL DE TRIBUTOS | B36: =B30+B32+B33+B34+B35 -> 54468.167 | C36: =C30+C32+C33+C34+C35 -> 54468.167 | D36: =D30+D32+D33+D34+D35 -> 54468.167 | E36: =E30+E32+E33+E34+E35 -> 54468.167 | F36: =F30+F32+F33+F34+F35 -> 68940.004 | G36: =G30+G32+G33+G34+G35 -> 68940.004 | H36: =H30+H32+H33+H34+H35 -> 68940.004 | I36: =I30+I32+I33+I34+I35 -> 68940.004 | J36: =SUM(B36:E36) -> 217872.67 | K36: =SUM(F36:I36) -> 275760.02
A37: Carga tributária / Receita Bruta | B37: =IFERROR(B36/B26,"-") -> 0.23312037 | C37: =IFERROR(C36/C26,"-") -> 0.23312037 | D37: =IFERROR(D36/D26,"-") -> 0.23312037 | E37: =IFERROR(E36/E26,"-") -> 0.23312037 | F37: =IFERROR(F36/F26,"-") -> 0.23807942 | G37: =IFERROR(G36/G26,"-") -> 0.23807942 | H37: =IFERROR(H36/H26,"-") -> 0.23807942 | I37: =IFERROR(I36/I26,"-") -> 0.23807942 | ... K37: =IFERROR(K36/K26,"-") -> 0.23807942
A38: Resultado após tributos | B38: =B8-B36 -> 179180.08 | C38: =C8-C36 -> 179180.08 | D38: =D8-D36 -> 179180.08 | E38: =E8-E36 -> 179180.08 | F38: =F8-F36 -> 220627.25 | G38: =G8-G36 -> 220627.25 | H38: =H8-H36 -> 220627.25 | I38: =I8-I36 -> 220627.25 | J38: =SUM(B38:E38) -> 716720.33 | K38: =SUM(F38:I38) -> 882508.98

Sheet Projeções 2028-2036
A1: PROJEÇÃO TRIBUTÁRIA 2028–2036 — LUCRO PRESUMIDO E LUCRO REAL
A2: Empresa de serviços. Azul = input | Preto = fórmula | Verde = link. Estrutura apenas — preencher receitas e despesas. Alíquotas de ISS/IBS seguem a transição da EC 132/2023.
A4: 1. PREMISSAS E ALÍQUOTAS — LUCRO PRESUMIDO
A5: Item | B5: 2028 | C5: 2029 | D5: 2030 | E5: 2031 | F5: 2032 | G5: 2033 | H5: 2034 | I5: 2035 | J5: 2036 | K5: Observações
A6: Receita Bruta | B6: =Modelo!O200 -> 1158269.3 | C6: =Modelo!P200 -> 1369985.6 | D6: =Modelo!Q200 -> 1573672.4 | E6: =Modelo!R200 -> 1774206.3 | F6: =Modelo!S200 -> 1968116.4 | G6: =Modelo!T200 -> 2161338.6 | H6: =Modelo!U200 -> 2355790.6 | I6: =Modelo!V200 -> 2553081.9 | J6: =Modelo!W200 -> 2754892.8 | K6: Input — preencher
A7: (-) Deduções da Receita Bruta | K7: Devoluções, descontos e cancelamentos
A8: (=) Receita Líquida | B8: =B6-B7 -> 1158269.3 | C8: =C6-C7 -> 1369985.6 | D8: =D6-D7 -> 1573672.4 | E8: =E6-E7 -> 1774206.3 | F8: =F6-F7 -> 1968116.4 | G8: =G6-G7 -> 2161338.6 | H8: =H6-H7 -> 2355790.6 | I8: =I6-I7 -> 2553081.9 | J8: =J6-J7 -> 2754892.8
A9: Presunção IRPJ | B9: 0.32 | C9: 0.32 | D9: 0.32 | E9: 0.32 | F9: 0.32 | G9: 0.32 | H9: 0.32 | I9: 0.32 | J9: 0.32 | K9: 32% — prestação de serviços em geral
A10: Presunção CSLL | B10: 0.32 | C10: 0.32 | D10: 0.32 | E10: 0.32 | F10: 0.32 | G10: 0.32 | H10: 0.32 | I10: 0.32 | J10: 0.32 | K10: 32% — prestação de serviços em geral
A11: IRPJ | B11: 0.15 | C11: 0.15 | D11: 0.15 | E11: 0.15 | F11: 0.15 | G11: 0.15 | H11: 0.15 | I11: 0.15 | J11: 0.15 | K11: Não alterado pela reforma
A12: IRPJ — Adicional | B12: 0.1 | C12: 0.1 | D12: 0.1 | E12: 0.1 | F12: 0.1 | G12: 0.1 | H12: 0.1 | I12: 0.1 | J12: 0.1 | K12: Sobre a base presumida que exceder o limite
A13: Limite anual do adicional (R$) | B13: 240000 | C13: 240000 | D13: 240000 | E13: 240000 | F13: 240000 | G13: 240000 | H13: 240000 | I13: 240000 | J13: 240000 | K13: R$ 20.000/mês × 12 meses
A14: CSLL | B14: 0.09 | C14: 0.09 | D14: 0.09 | E14: 0.09 | F14: 0.09 | G14: 0.09 | H14: 0.09 | I14: 0.09 | J14: 0.09 | K14: Não alterada pela reforma
A15: ISS | B15: 0.05 | C15: 0.05 | D15: 0.05 | E15: 0.05 | F15: 0.05 | G15: 0.05 | H15: 0.05 | I15: 0.05 | J15: 0.05 | K15: Redução de 10%/ano entre 2029 e 2032; extinto em 2033
A16: IBS | B16: 0.001 | C16: 0.001 | D16: 0.001 | E16: 0.001 | F16: 0.001 | G16: 0.001 | H16: 0.001 | I16: 0.001 | J16: 0.001 | K16: Transição: 10/20/30/40% da alíquota cheia (15,60%) em 2029–2032; cheia a partir de 2033
A17: CBS | B17: 0.099 | C17: 0.099 | D17: 0.099 | E17: 0.099 | F17: 0.099 | G17: 0.099 | H17: 0.099 | I17: 0.099 | J17: 0.099 | K17: Substitui PIS/COFINS; cheia desde 2027. CBS + IBS ≈ 26,5% em regime pleno
A18: PIS / COFINS | B18: Extintos | C18: Extintos | D18: Extintos | E18: Extintos | F18: Extintos | G18: Extintos | H18: Extintos | I18: Extintos | J18: Extintos | K18: Extintos desde 2027 — substituídos pela CBS
A20: 2. APURAÇÃO ANUAL — LUCRO PRESUMIDO
A21: Item | B21: =B5 -> 2028 | C21: =C5 -> 2029 | D21: =D5 -> 2030 | E21: =E5 -> 2031 | F21: =F5 -> 2032 | G21: =G5 -> 2033 | H21: =H5 -> 2034 | I21: =I5 -> 2035 | J21: =J5 -> 2036 | K21: Total 2028–2036
A22: Receita Bruta | B22: =B6 -> 1158269.3 | C22: =C6 -> 1369985.6 | D22: =D6 -> 1573672.4 | E22: =E6 -> 1774206.3 | F22: =F6 -> 1968116.4 | G22: =G6 -> 2161338.6 | H22: =H6 -> 2355790.6 | I22: =I6 -> 2553081.9 | J22: =J6 -> 2754892.8 | K22: =SUM(B22:J22) -> 17669354
A23: Base de cálculo IRPJ (presumida) | B23: =B22*B9 -> 370646.18 | C23: =C22*C9 -> 438395.38 | D23: =D22*D9 -> 503575.15 | E23: =E22*E9 -> 567746.01 | F23: =F22*F9 -> 629797.26 | G23: =G22*G9 -> 691628.34 | H23: =H22*H9 -> 753853 | I23: =I22*I9 -> 816986.2 | J23: =J22*J9 -> 881565.68 | K23: =SUM(B23:J23) -> 5654193.2
A24: IRPJ | B24: =B23*B11 -> 55596.927 | C24: =C23*C11 -> 65759.307 | D24: =D23*D11 -> 75536.273 | E24: =E23*E11 -> 85161.901 | F24: =F23*F11 -> 94469.589 | G24: =G23*G11 -> 103744.25 | H24: =H23*H11 -> 113077.95 | I24: =I23*I11 -> 122547.93 | J24: =J23*J11 -> 132234.85 | K24: =SUM(B24:J24) -> 848128.98
A25: IRPJ — Adicional | B25: =IF(B23>B13,(B23-B13)*B12,0) -> 13064.618 | C25: =IF(C23>C13,(C23-C13)*C12,0) -> 19839.538 | D25: =IF(D23>D13,(D23-D13)*D12,0) -> 26357.515 | E25: =IF(E23>E13,(E23-E13)*E12,0) -> 32774.601 | F25: =IF(F23>F13,(F23-F13)*F12,0) -> 38979.726 | G25: =IF(G23>G13,(G23-G13)*G12,0) -> 45162.834 | H25: =IF(H23>H13,(H23-H13)*H12,0) -> 51385.3 | I25: =IF(I23>I13,(I23-I13)*I12,0) -> 57698.62 | J25: =IF(J23>J13,(J23-J13)*J12,0) -> 64156.568 | K25: =SUM(B25:J25) -> 349419.32
A26: IRPJ Total | B26: =B24+B25 -> 68661.545 | C26: =C24+C25 -> 85598.845 | D26: =D24+D25 -> 101893.79 | E26: =E24+E25 -> 117936.5 | F26: =F24+F25 -> 133449.32 | G26: =G24+G25 -> 148907.09 | H26: =H24+H25 -> 164463.25 | I26: =I24+I25 -> 180246.55 | J26: =J24+J25 -> 196391.42 | K26: =SUM(B26:J26) -> 1197548.3
A27: Base de cálculo CSLL (presumida) | B27: =B22*B10 -> 370646.18 | C27: =C22*C10 -> 438395.38 | D27: =D22*D10 -> 503575.15 | E27: =E22*E10 -> 567746.01 | F27: =F22*F10 -> 629797.26 | G27: =G22*G10 -> 691628.34 | H27: =H22*H10 -> 753853 | I27: =I22*I10 -> 816986.2 | J27: =J22*J10 -> 881565.68 | K27: =SUM(B27:J27) -> 5654193.2
A28: CSLL | B28: =B27*B14 -> 33358.156 | C28: =C27*C14 -> 39455.584 | D28: =D27*D14 -> 45321.764 | E28: =E27*E14 -> 51097.14 | F28: =F27*F14 -> 56681.754 | G28: =G27*G14 -> 62246.551 | H28: =H27*H14 -> 67846.77 | I28: =I27*I14 -> 73528.758 | J28: =J27*J14 -> 79340.911 | K28: =SUM(B28:J28) -> 508877.39
A29: ISS | B29: =B22*B15 -> 57913.466 | C29: =C22*C15 -> 68499.278 | D29: =D22*D15 -> 78683.618 | E29: =E22*E15 -> 88710.313 | F29: =F22*F15 -> 98405.822 | G29: =G22*G15 -> 108066.93 | H29: =H22*H15 -> 117789.53 | I29: =I22*I15 -> 127654.09 | J29: =J22*J15 -> 137744.64 | K29: =SUM(B29:J29) -> 883467.69
A30: IBS | B30: =B22*B16 -> 1158.2693 | C30: =C22*C16 -> 1369.9856 | D30: =D22*D16 -> 1573.6724 | E30: =E22*E16 -> 1774.2063 | F30: =F22*F16 -> 1968.1164 | G30: =G22*G16 -> 2161.3386 | H30: =H22*H16 -> 2355.7906 | I30: =I22*I16 -> 2553.0819 | J30: =J22*J16 -> 2754.8928 | K30: =SUM(B30:J30) -> 17669.354
A31: CBS | B31: =B22*B17 -> 114668.66 | C31: =C22*C17 -> 135628.57 | D31: =D22*D17 -> 155793.56 | E31: =E22*E17 -> 175646.42 | F31: =F22*F17 -> 194843.53 | G31: =G22*G17 -> 213972.52 | H31: =H22*H17 -> 233223.27 | I31: =I22*I17 -> 252755.11 | J31: =J22*J17 -> 272734.38 | K31: =SUM(B31:J31) -> 1749266
A32: TOTAL DE TRIBUTOS | B32: =B26+B28+B29+B30+B31 -> 275760.1 | C32: =C26+C28+C29+C30+C31 -> 330552.26 | D32: =D26+D28+D29+D30+D31 -> 383266.4 | E32: =E26+E28+E29+E30+E31 -> 435164.58 | F32: =F26+F28+F29+F30+F31 -> 485348.54 | G32: =G26+G28+G29+G30+G31 -> 535354.42 | H32: =H26+H28+H29+H30+H31 -> 585678.62 | I32: =I26+I28+I29+I30+I31 -> 636737.59 | J32: =J26+J28+J29+J30+J31 -> 688966.25 | K32: =SUM(B32:J32) -> 4356828.8
A33: Carga tributária / Receita Bruta | B33: =IFERROR(B32/B22,"-") -> 0.23807943 | C33: =IFERROR(C32/C22,"-") -> 0.24128157 | D33: =IFERROR(D32/D22,"-") -> 0.24354905 | E33: =IFERROR(E32/E22,"-") -> 0.24527282 | F33: =IFERROR(F32/F22,"-") -> 0.2466056 | G33: =IFERROR(G32/G22,"-") -> 0.24769577 | H33: =IFERROR(H32/H22,"-") -> 0.24861234 | I33: =IFERROR(I32/I22,"-") -> 0.2493996 | ... K33: =IFERROR(K32/K22,"-") -> 0.24657544
A34: Resultado após tributos | B34: =B8-B32 -> 882509.22 | C34: =C8-C32 -> 1039433.3 | D34: =D8-D32 -> 1190405.9 | E34: =E8-E32 -> 1339041.7 | F34: =F8-F32 -> 1482767.9 | G34: =G8-G32 -> 1625984.2 | H34: =H8-H32 -> 1770112 | I34: =I8-I32 -> 1916344.3 | J34: =J8-J32 -> 2065926.5 | K34: =SUM(B34:J34) -> 13312525
A36: 3. PREMISSAS E ALÍQUOTAS — LUCRO REAL
A37: Item | B37: =B5 -> 2028 | C37: =C5 -> 2029 | D37: =D5 -> 2030 | E37: =E5 -> 2031 | F37: =F5 -> 2032 | G37: =G5 -> 2033 | H37: =H5 -> 2034 | I37: =I5 -> 2035 | J37: =J5 -> 2036 | K37: Observações
A38: Receita Bruta | B38: =B6 -> 1158269.3 | C38: =C6 -> 1369985.6 | D38: =D6 -> 1573672.4 | E38: =E6 -> 1774206.3 | F38: =F6 -> 1968116.4 | G38: =G6 -> 2161338.6 | H38: =H6 -> 2355790.6 | I38: =I6 -> 2553081.9 | J38: =J6 -> 2754892.8 | K38: Input — preencher
A39: (-) Deduções da Receita Bruta | B39: =B38*(B51+B52+B53) -> 173740.4 | C39: =C38*(C51+C52+C53) -> 205497.83 | D39: =D38*(D51+D52+D53) -> 236050.85 | E39: =E38*(E51+E52+E53) -> 266130.94 | F39: =F38*(F51+F52+F53) -> 295217.47 | G39: =G38*(G51+G52+G53) -> 324200.79 | H39: =H38*(H51+H52+H53) -> 353368.6 | I39: =I38*(I51+I52+I53) -> 382962.28 | J39: =J38*(J51+J52+J53) -> 413233.91 | K39: Devoluções, descontos e cancelamentos
A40: (=) Receita Líquida | B40: =B38-B39 -> 984528.92 | C40: =C38-C39 -> 1164487.7 | D40: =D38-D39 -> 1337621.5 | E40: =E38-E39 -> 1508075.3 | F40: =F38-F39 -> 1672899 | G40: =G38-G39 -> 1837137.8 | H40: =H38-H39 -> 2002422 | I40: =I38-I39 -> 2170119.6 | J40: =J38-J39 -> 2341658.8
A41: (-) Despesas Dedutíveis | K41: Custos e despesas necessários à atividade (art. 311 RIR/18)
A42: (=) Resultado Contábil (LAIR) | B42: =B40-B41 -> 984528.92 | C42: =C40-C41 -> 1164487.7 | D42: =D40-D41 -> 1337621.5 | E42: =E40-E41 -> 1508075.3 | F42: =F40-F41 -> 1672899 | G42: =G40-G41 -> 1837137.8 | H42: =H40-H41 -> 2002422 | I42: =I40-I41 -> 2170119.6 | J42: =J40-J41 -> 2341658.8
A43: (+) Adições — despesas indedutíveis | K43: Multas, brindes, doações e provisões não dedutíveis
...
